# Assert

<!--introduced_in=v0.1.21-->

> Stabilità: 2 - Stable

The `assert` module provides a simple set of assertion tests that can be used to test invariants.

A `strict` and a `legacy` mode exist, while it is recommended to only use [`strict mode`][].

For more information about the used equality comparisons see [MDN's guide on equality comparisons and sameness](https://developer.mozilla.org/en-US/docs/Web/JavaScript/Equality_comparisons_and_sameness).

## Classe: assert.AssertionError

Una sottoclasse di `Error` che indica il fallimento di un assertion. All errors thrown by the `assert` module will be instances of the `AssertionError` class.

### nuova assert.AssertionError(options)

<!-- YAML
added: v0.1.21
-->

* `options` {Object} 
  * `message` {string} If provided, the error message is going to be set to this value.
  * `actual` {any} The `actual` property on the error instance is going to contain this value. Internally used for the `actual` error input in case e.g., [`assert.strictEqual()`] is used.
  * `expected` {any} The `expected` property on the error instance is going to contain this value. Internally used for the `expected` error input in case e.g., [`assert.strictEqual()`] is used.
  * `operator` {string} The `operator` property on the error instance is going to contain this value. Internally used to indicate what operation was used for comparison (or what assertion function triggered the error).
  * `stackStartFn` {Function} If provided, the generated stack trace is going to remove all frames up to the provided function.

Una sottoclasse di `Error` che indica il fallimento di un assertion.

All instances contain the built-in `Error` properties (`message` and `name`) and:

* `actual` {any} Set to the actual value in case e.g., [`assert.strictEqual()`] is used.
* `expected` {any} Set to the expected value in case e.g., [`assert.strictEqual()`] is used.
* `generatedMessage` {boolean} Indicates if the message was auto-generated (`true`) or not.
* `code` {string} This is always set to the string `ERR_ASSERTION` to indicate that the error is actually an assertion error.
* `operator` {string} Imposta sul valore operator passato.

```js
const assert = require('assert');

// Genera un AssertionError per confrontare il messaggio di errore in un secondo momento:
const { message } = new assert.AssertionError({
  actual: 1,
  expected: 2,
  operator: 'strictEqual'
});

// Verifica l'output dell'errore:
try {
  assert.strictEqual(1, 2);
} catch (err) {
  assert(err instanceof assert.AssertionError);
  assert.strictEqual(err.message, message);
  assert.strictEqual(err.name, 'AssertionError [ERR_ASSERTION]');
  assert.strictEqual(err.actual, 1);
  assert.strictEqual(err.expected, 2);
  assert.strictEqual(err.code, 'ERR_ASSERTION');
  assert.strictEqual(err.operator, 'strictEqual');
  assert.strictEqual(err.generatedMessage, true);
}
```

## Strict mode

<!-- YAML
added: v9.9.0
changes:

  - version: v9.9.0
    pr-url: https://github.com/nodejs/node/pull/17615
    description: Added error diffs to the strict mode
  - version: v9.9.0
    pr-url: https://github.com/nodejs/node/pull/17002
    description: Added strict mode to the assert module.
-->

When using the `strict mode`, any `assert` function will use the equality used in the strict function mode. So [`assert.deepEqual()`][] will, for example, work the same as [`assert.deepStrictEqual()`][].

On top of that, error messages which involve objects produce an error diff instead of displaying both objects. Questo non succede nella legacy mode.

Ci si può accedere utilizzando:

```js
const assert = require('assert').strict;
```

Esempio di error diff:

```js
const assert = require('assert').strict;

assert.deepEqual([[[1, 2, 3]], 4, 5], [[[1, 2, '3']], 4, 5]);
// AssertionError: Input A expected to strictly deep-equal input B:
// + expected - actual ... Lines skipped
//
//   [
//     [
// ...
//       2,
// -     3
// +     '3'
//     ],
// ...
//     5
//   ]
```

Per disattivare i colori, utilizza la variabile di ambiente `NODE_DISABLE_COLORS`. Si prega di notare che questa disattiverà anche i colori nel REPL.

## Legacy mode

> Stabilità: 0 - Obsoleto: Utilizza invece la strict mode.

When accessing `assert` directly instead of using the `strict` property, the [Abstract Equality Comparison](https://tc39.github.io/ecma262/#sec-abstract-equality-comparison) will be used for any function without "strict" in its name, such as [`assert.deepEqual()`][].

Ci si può accedere utilizzando:

```js
const assert = require('assert');
```

It is recommended to use the [`strict mode`][] instead as the [Abstract Equality Comparison](https://tc39.github.io/ecma262/#sec-abstract-equality-comparison) can often have surprising results. This is especially true for [`assert.deepEqual()`][], where the comparison rules are lax:

```js
// ATTENZIONE: Questo non lancia un AssertionError!
assert.deepEqual(/a/gi, new Date());
```

## assert(value[, message])

<!-- YAML
added: v0.5.9
-->

* `value` {any} The input that is checked for being truthy.
* `message` {string|Error}

Un alias di [`assert.ok()`][].

## assert.deepEqual(actual, expected[, message])

<!-- YAML
added: v0.1.21
changes:

  - version: v9.0.0
    pr-url: https://github.com/nodejs/node/pull/15001
    description: The `Error` names and messages are now properly compared
  - version: v8.0.0
    pr-url: https://github.com/nodejs/node/pull/12142
    description: The `Set` and `Map` content is also compared
  - version: v6.4.0, v4.7.1
    pr-url: https://github.com/nodejs/node/pull/8002
    description: Typed array slices are handled correctly now.
  - version: v6.1.0, v4.5.0
    pr-url: https://github.com/nodejs/node/pull/6432
    description: Objects with circular references can be used as inputs now.
  - version: v5.10.1, v4.4.3
    pr-url: https://github.com/nodejs/node/pull/5910
    description: Handle non-`Uint8Array` typed arrays correctly.
-->

* `actual` {any}
* `expected` {any}
* `message` {string|Error}

**Strict mode**

Un alias di [`assert.deepStrictEqual()`][].

**Legacy mode**

> Stabilità: 0 - Obsoleto: Utilizza invece [`assert.deepStrictEqual()`][].

Test per la deep equality tra i parametri `actual` ed `expected`. Primitive values are compared with the [Abstract Equality Comparison](https://tc39.github.io/ecma262/#sec-abstract-equality-comparison) ( `==` ).

Sono prese in considerazione solo [le proprietà "own" enumerabili](https://developer.mozilla.org/en-US/docs/Web/JavaScript/Enumerability_and_ownership_of_properties). The [`assert.deepEqual()`][] implementation does not test the [`[[Prototype]]`](https://tc39.github.io/ecma262/#sec-ordinary-object-internal-methods-and-internal-slots) of objects or enumerable own [`Symbol`][] properties. For such checks, consider using [`assert.deepStrictEqual()`][] instead. [`assert.deepEqual()`][] può avere risultati potenzialmente sorprendenti. The following example does not throw an `AssertionError` because the properties on the [`RegExp`][] object are not enumerable:

```js
// ATTENZIONE: Questo non lancia un AssertionError!
assert.deepEqual(/a/gi, new Date());
```

Viene fatta un'eccezione per [`Map`][] e [`Set`][]. `Map`s and `Set`s have their contained items compared too, as expected.

"Deep" equality means that the enumerable "own" properties of child objects are evaluated also:

```js
const assert = require('assert');

const obj1 = {
  a: {
    b: 1
  }
};
const obj2 = {
  a: {
    b: 2
  }
};
const obj3 = {
  a: {
    b: 1
  }
};
const obj4 = Object.create(obj1);

assert.deepEqual(obj1, obj1);
// OK

// Values of b are different:
assert.deepEqual(obj1, obj2);
// AssertionError: { a: { b: 1 } } deepEqual { a: { b: 2 } }

assert.deepEqual(obj1, obj3);
// OK

// Prototypes are ignored:
assert.deepEqual(obj1, obj4);
// AssertionError: { a: { b: 1 } } deepEqual {}
```

If the values are not equal, an `AssertionError` is thrown with a `message` property set equal to the value of the `message` parameter. If the `message` parameter is undefined, a default error message is assigned. If the `message` parameter is an instance of an [`Error`][] then it will be thrown instead of the `AssertionError`.

## assert.deepStrictEqual(actual, expected[, message])

<!-- YAML
added: v1.2.0
changes:

  - version: v9.0.0
    pr-url: https://github.com/nodejs/node/pull/15169
    description: Enumerable symbol properties are now compared.
  - version: v9.0.0
    pr-url: https://github.com/nodejs/node/pull/15036
    description: The `NaN` is now compared using the
              [SameValueZero](https://tc39.github.io/ecma262/#sec-samevaluezero)
              comparison.
  - version: v8.5.0
    pr-url: https://github.com/nodejs/node/pull/15001
    description: The `Error` names and messages are now properly compared
  - version: v8.0.0
    pr-url: https://github.com/nodejs/node/pull/12142
    description: The `Set` and `Map` content is also compared
  - version: v6.4.0, v4.7.1
    pr-url: https://github.com/nodejs/node/pull/8002
    description: Typed array slices are handled correctly now.
  - version: v6.1.0
    pr-url: https://github.com/nodejs/node/pull/6432
    description: Objects with circular references can be used as inputs now.
  - version: v5.10.1, v4.4.3
    pr-url: https://github.com/nodejs/node/pull/5910
    description: Handle non-`Uint8Array` typed arrays correctly.
-->

* `actual` {any}
* `expected` {any}
* `message` {string|Error}

Test per la deep equality tra i parametri `actual` ed `expected`. "Deep" equality means that the enumerable "own" properties of child objects are recursively evaluated also by the following rules.

### Dettagli di confronto

* Primitive values are compared using the [SameValue Comparison](https://tc39.github.io/ecma262/#sec-samevalue), used by [`Object.is()`][].
* [Type tags](https://tc39.github.io/ecma262/#sec-object.prototype.tostring) degli objects dovrebbero essere gli stessi.
* [`[[Prototype]]`](https://tc39.github.io/ecma262/#sec-ordinary-object-internal-methods-and-internal-slots) of objects are compared using the [Strict Equality Comparison](https://tc39.github.io/ecma262/#sec-strict-equality-comparison).
* Sono prese in considerazione solo [le proprietà "own" enumerabili](https://developer.mozilla.org/en-US/docs/Web/JavaScript/Enumerability_and_ownership_of_properties).
* [`Error`][] names and messages are always compared, even if these are not enumerable properties.
* Anche le proprietà own [`Symbol`][] enumerabili vengono confrontate.
* Gli [Object wrappers](https://developer.mozilla.org/en-US/docs/Glossary/Primitive#Primitive_wrapper_objects_in_JavaScript) vengono confrontati sia come objects che come valori che hanno subito l'unwrap.
* Le proprietà dell'`Object` vengono confrontate in modo non ordinato.
* Le `Map` key ed i `Set` item vengono confrontati in modo non ordinato.
* Recursion stops when both sides differ or both sides encounter a circular reference.
* I confronti [`WeakMap`][] e [`WeakSet`][] non si basano sui loro valori. Vedi sotto per ulteriori dettagli.

```js
const assert = require('assert').strict;

// Questo fallisce perché 1 !== '1'.
assert.deepStrictEqual({ a: 1 }, { a: '1' });
// AssertionError: Input A expected to strictly deep-equal input B:
// + expected - actual
//   {
// -   a: 1
// +   a: '1'
//   }

// I seguenti objects non hanno proprietà proprie
const date = new Date();
const object = {};
const fakeDate = {};
Object.setPrototypeOf(fakeDate, Date.prototype);

// [[Prototype]] diverso:
assert.deepStrictEqual(object, fakeDate);
// AssertionError: Input A expected to strictly deep-equal input B:
// + expected - actual
// - {}
// + Date {}

// Type tags diversi:
assert.deepStrictEqual(date, fakeDate);
// AssertionError: Input A expected to strictly deep-equal input B:
// + expected - actual
// - 2018-04-26T00:49:08.604Z
// + Date {}

assert.deepStrictEqual(NaN, NaN);
// OK, a causa del SameValue comparison

// Numeri che hanno subito l'unwrap diversi:
assert.deepStrictEqual(new Number(1), new Number(2));
// AssertionError: Input A expected to strictly deep-equal input B:
// + expected - actual
// - [Number: 1]
// + [Number: 2]

assert.deepStrictEqual(new String('foo'), Object('foo'));
// OK perché l'object e la stringa sono identici una volta che hanno subito l'unwrap.

assert.deepStrictEqual(-0, -0);
// OK

// Diversi zeri usando il SameValue Comparison:
assert.deepStrictEqual(0, -0);
// AssertionError: Input A expected to strictly deep-equal input B:
// + expected - actual
// - 0
// + -0

const symbol1 = Symbol();
const symbol2 = Symbol();
assert.deepStrictEqual({ [symbol1]: 1 }, { [symbol1]: 1 });
// OK, perché è lo stesso symbol su entrambi gli objects.
assert.deepStrictEqual({ [symbol1]: 1 }, { [symbol2]: 1 });
// AssertionError [ERR_ASSERTION]: Input objects non 
identici:
// {
//   [Symbol()]: 1
// }

const weakMap1 = new WeakMap();
const weakMap2 = new WeakMap([[{}, {}]]);
const weakMap3 = new WeakMap();
weakMap3.unequal = true;

assert.deepStrictEqual(weakMap1, weakMap2);
// OK, perché è impossibile confrontare le voci

// Fallisce perché weakMap3 ha una proprietà che weakMap1 non contiene:
assert.deepStrictEqual(weakMap1, weakMap3);
// AssertionError: Input A expected to strictly deep-equal input B:
// + expected - actual
//   WeakMap {
// -   [items unknown]
// +   [items unknown],
// +   unequal: true
//   }
```

If the values are not equal, an `AssertionError` is thrown with a `message` property set equal to the value of the `message` parameter. If the `message` parameter is undefined, a default error message is assigned. If the `message` parameter is an instance of an [`Error`][] then it will be thrown instead of the `AssertionError`.

## assert.doesNotReject(asyncFn\[, error\]\[, message\])

<!-- YAML
added: v10.0.0
-->

* `asyncFn` {Function|Promise}
* `error` {RegExp|Function}
* `message` {string}

Awaits the `asyncFn` promise or, if `asyncFn` is a function, immediately calls the function and awaits the returned promise to complete. It will then check that the promise is not rejected.

If `asyncFn` is a function and it throws an error synchronously, `assert.doesNotReject()` will return a rejected `Promise` with that error. If the function does not return a promise, `assert.doesNotReject()` will return a rejected `Promise` with an [`ERR_INVALID_RETURN_VALUE`][] error. In both cases the error handler is skipped.

Using `assert.doesNotReject()` is actually not useful because there is little benefit in catching a rejection and then rejecting it again. Instead, consider adding a comment next to the specific code path that should not reject and keep error messages as expressive as possible.

If specified, `error` can be a [`Class`][], [`RegExp`][] or a validation function. Vedi [`assert.throws()`][] per maggiori dettagli.

Besides the async nature to await the completion behaves identically to [`assert.doesNotThrow()`][].

```js
(async () => {
  await assert.doesNotReject(
    async () => {
      throw new TypeError('Wrong value');
    },
    SyntaxError
  );
})();
```

```js
assert.doesNotReject(Promise.reject(new TypeError('Wrong value')))
  .then(() => {
    // ...
  });
```

## assert.doesNotThrow(fn\[, error\]\[, message\])

<!-- YAML
added: v0.1.21
changes:

  - version: v5.11.0, v4.4.5
    pr-url: https://github.com/nodejs/node/pull/2407
    description: The `message` parameter is respected now.
  - version: v4.2.0
    pr-url: https://github.com/nodejs/node/pull/3276
    description: The `error` parameter can now be an arrow function.
-->

* `fn` {Function}
* `error` {RegExp|Function}
* `message` {string}

Asserts that the function `fn` does not throw an error.

Using `assert.doesNotThrow()` is actually not useful because there is no benefit in catching an error and then rethrowing it. Instead, consider adding a comment next to the specific code path that should not throw and keep error messages as expressive as possible.

When `assert.doesNotThrow()` is called, it will immediately call the `fn` function.

If an error is thrown and it is the same type as that specified by the `error` parameter, then an `AssertionError` is thrown. If the error is of a different type, or if the `error` parameter is undefined, the error is propagated back to the caller.

If specified, `error` can be a [`Class`][], [`RegExp`][] or a validation function. Vedi [`assert.throws()`][] per maggiori dettagli.

The following, for instance, will throw the [`TypeError`][] because there is no matching error type in the assertion:

```js
assert.doesNotThrow(
  () => {
    throw new TypeError('Wrong value');
  },
  SyntaxError
);
```

However, the following will result in an `AssertionError` with the message 'Got unwanted exception...':

```js
assert.doesNotThrow(
  () => {
    throw new TypeError('Wrong value');
  },
  TypeError
);
```

If an `AssertionError` is thrown and a value is provided for the `message` parameter, the value of `message` will be appended to the `AssertionError` message:

```js
assert.doesNotThrow(
  () => {
    throw new TypeError('Wrong value');
  },
  /Wrong value/,
  'Whoops'
);
// Genera: AssertionError: Ha un'eccezione indesiderata: Whoops
```

## assert.equal(actual, expected[, message])<!-- YAML
added: v0.1.21
-->

* `actual` {any}

* `expected` {any}

* `message` {string|Error}

**Strict mode**

Un alias di [`assert.strictEqual()`][].

**Legacy mode**

> Stabilità: 0 - Obsoleto: Utilizza invece [`assert.strictEqual()`][].

Tests shallow, coercive equality between the `actual` and `expected` parameters using the [Abstract Equality Comparison](https://tc39.github.io/ecma262/#sec-abstract-equality-comparison) ( `==` ).

```js
const assert = require('assert');

assert.equal(1, 1);
// OK, 1 == 1
assert.equal(1, '1');
// OK, 1 == '1'

assert.equal(1, 2);
// AssertionError: 1 == 2
assert.equal({ a: { b: 1 } }, { a: { b: 1 } });
// AssertionError: { a: { b: 1 } } == { a: { b: 1 } }
```

If the values are not equal, an `AssertionError` is thrown with a `message` property set equal to the value of the `message` parameter. If the `message` parameter is undefined, a default error message is assigned. If the `message` parameter is an instance of an [`Error`][] then it will be thrown instead of the `AssertionError`.

## assert.fail([message])<!-- YAML
added: v0.1.21
-->

* `message` {string|Error} **Default:** `'Failed'`

Throws an `AssertionError` with the provided error message or a default error message. If the `message` parameter is an instance of an [`Error`][] then it will be thrown instead of the `AssertionError`.

```js
const assert = require('assert').strict;

assert.fail();
// AssertionError [ERR_ASSERTION]: Failed

assert.fail('boom');
// AssertionError [ERR_ASSERTION]: boom

assert.fail(new TypeError('need array'));
// TypeError: need array
```

L'utilizzo di `assert.fail()` con più di due argomenti è possibile ma obsoleto. Vedi sotto per ulteriori dettagli.

## assert.fail(actual, expected[, message[, operator[, stackStartFn]]])<!-- YAML
added: v0.1.21
changes:

  - version: v10.0.0
    pr-url: https://github.com/nodejs/node/pull/18418
    description: Calling `assert.fail()` with more than one argument is
                 deprecated and emits a warning.
-->

* `actual` {any}
* `expected` {any}
* `message` {string|Error}
* `operator` {string} **Default:** `'!='`
* `stackStartFn` {Function} **Default:** `assert.fail`

> Stability: 0 - Deprecated: Use `assert.fail([message])` or other assert functions instead.

If `message` is falsy, the error message is set as the values of `actual` and `expected` separated by the provided `operator`. If just the two `actual` and `expected` arguments are provided, `operator` will default to `'!='`. If `message` is provided as third argument it will be used as the error message and the other arguments will be stored as properties on the thrown object. If `stackStartFn` is provided, all stack frames above that function will be removed from stacktrace (see [`Error.captureStackTrace`]). If no arguments are given, the default message `Failed` will be used.

```js
const assert = require('assert').strict;

assert.fail('a', 'b');
// AssertionError [ERR_ASSERTION]: 'a' != 'b'

assert.fail(1, 2, undefined, '>');
// AssertionError [ERR_ASSERTION]: 1 > 2

assert.fail(1, 2, 'fail');
// AssertionError [ERR_ASSERTION]: fail

assert.fail(1, 2, 'whoops', '>');
// AssertionError [ERR_ASSERTION]: whoops

assert.fail(1, 2, new TypeError('need array'));
// TypeError: need array
```

In the last three cases `actual`, `expected`, and `operator` have no influence on the error message.

Example use of `stackStartFn` for truncating the exception's stacktrace:

```js
function suppressFrame() {
  assert.fail('a', 'b', undefined, '!==', suppressFrame);
}
suppressFrame();
// AssertionError [ERR_ASSERTION]: 'a' !== 'b'
//     at repl:1:1
//     at ContextifyScript.Script.runInThisContext (vm.js:44:33)
//     ...
```

## assert.ifError(value)<!-- YAML
added: v0.1.97
changes:

  - version: v10.0.0
    pr-url: https://github.com/nodejs/node/pull/18247
    description: Instead of throwing the original error it is now wrapped into
                 an `AssertionError` that contains the full stack trace.
  - version: v10.0.0
    pr-url: https://github.com/nodejs/node/pull/18247
    description: Value may now only be `undefined` or `null`. Before all falsy
                 values were handled the same as `null` and did not throw.
-->

* `value` {any}

Genera `value` se `value` non è `undefined` o `null`. This is useful when testing the `error` argument in callbacks. The stack trace contains all frames from the error passed to `ifError()` including the potential new frames for `ifError()` itself.

```js
const assert = require('assert').strict;

assert.ifError(null);
// OK
assert.ifError(0);
// AssertionError [ERR_ASSERTION]: ifError got unwanted exception: 0
assert.ifError('error');
// AssertionError [ERR_ASSERTION]: ifError got unwanted exception: 'error'
assert.ifError(new Error());
// AssertionError [ERR_ASSERTION]: ifError got unwanted exception: Error

// Creare alcuni frames di errore casuali.
let err;
(function errorFrame() {
  err = new Error('test error');
})();

(function ifErrorFrame() {
  assert.ifError(err);
})();
// AssertionError [ERR_ASSERTION]: ifError got unwanted exception: test error
//     at ifErrorFrame
//     at errorFrame
```

## assert.notDeepEqual(actual, expected[, message])<!-- YAML
added: v0.1.21
changes:

  - version: v9.0.0
    pr-url: https://github.com/nodejs/node/pull/15001
    description: The `Error` names and messages are now properly compared
  - version: v8.0.0
    pr-url: https://github.com/nodejs/node/pull/12142
    description: The `Set` and `Map` content is also compared
  - version: v6.4.0, v4.7.1
    pr-url: https://github.com/nodejs/node/pull/8002
    description: Typed array slices are handled correctly now.
  - version: v6.1.0, v4.5.0
    pr-url: https://github.com/nodejs/node/pull/6432
    description: Objects with circular references can be used as inputs now.
  - version: v5.10.1, v4.4.3
    pr-url: https://github.com/nodejs/node/pull/5910
    description: Handle non-`Uint8Array` typed arrays correctly.
-->

* `actual` {any}
* `expected` {any}
* `message` {string|Error}

**Strict mode**

Un alias di [`assert.notDeepStrictEqual()`][].

**Legacy mode**

> Stabilità: 0 - Obsoleto: Utilizza invece [`assert.notDeepStrictEqual()`][].

Test per qualsiasi deep inequality. Opposto di [`assert.deepEqual()`][].

```js
const assert = require('assert');

const obj1 = {
  a: {
    b: 1
  }
};
const obj2 = {
  a: {
    b: 2
  }
};
const obj3 = {
  a: {
    b: 1
  }
};
const obj4 = Object.create(obj1);

assert.notDeepEqual(obj1, obj1);
// AssertionError: { a: { b: 1 } } notDeepEqual { a: { b: 1 } }

assert.notDeepEqual(obj1, obj2);
// OK

assert.notDeepEqual(obj1, obj3);
// AssertionError: { a: { b: 1 } } notDeepEqual { a: { b: 1 } }

assert.notDeepEqual(obj1, obj4);
// OK
```

If the values are deeply equal, an `AssertionError` is thrown with a `message` property set equal to the value of the `message` parameter. If the `message` parameter is undefined, a default error message is assigned. If the `message` parameter is an instance of an [`Error`][] then it will be thrown instead of the `AssertionError`.

## assert.notDeepStrictEqual(actual, expected[, message])<!-- YAML
added: v1.2.0
changes:

  - version: v9.0.0
    pr-url: https://github.com/nodejs/node/pull/15398
    description: The `-0` and `+0` are not considered equal anymore.
  - version: v9.0.0
    pr-url: https://github.com/nodejs/node/pull/15036
    description: The `NaN` is now compared using the
              [SameValueZero](https://tc39.github.io/ecma262/#sec-samevaluezero)
              comparison.
  - version: v9.0.0
    pr-url: https://github.com/nodejs/node/pull/15001
    description: The `Error` names and messages are now properly compared
  - version: v8.0.0
    pr-url: https://github.com/nodejs/node/pull/12142
    description: The `Set` and `Map` content is also compared
  - version: v6.4.0, v4.7.1
    pr-url: https://github.com/nodejs/node/pull/8002
    description: Typed array slices are handled correctly now.
  - version: v6.1.0
    pr-url: https://github.com/nodejs/node/pull/6432
    description: Objects with circular references can be used as inputs now.
  - version: v5.10.1, v4.4.3
    pr-url: https://github.com/nodejs/node/pull/5910
    description: Handle non-`Uint8Array` typed arrays correctly.
-->

* `actual` {any}
* `expected` {any}
* `message` {string|Error}

Test per la deep strict inequality. Opposto di [`assert.deepStrictEqual()`][].

```js
const assert = require('assert').strict;

assert.notDeepStrictEqual({ a: 1 }, { a: '1' });
// OK
```

If the values are deeply and strictly equal, an `AssertionError` is thrown with a `message` property set equal to the value of the `message` parameter. If the `message` parameter is undefined, a default error message is assigned. If the `message` parameter is an instance of an [`Error`][] then it will be thrown instead of the `AssertionError`.

## assert.notEqual(actual, expected[, message])<!-- YAML
added: v0.1.21
-->

* `actual` {any}

* `expected` {any}

* `message` {string|Error}

**Strict mode**

Un alias di [`assert.notStrictEqual()`][].

**Legacy mode**

> Stabilità: 0 - Obsoleto: Utilizza invece [`assert.notStrictEqual()`][].

Tests shallow, coercive inequality with the [Abstract Equality Comparison](https://tc39.github.io/ecma262/#sec-abstract-equality-comparison) ( `!=` ).

```js
const assert = require('assert');

assert.notEqual(1, 2);
// OK

assert.notEqual(1, 1);
// AssertionError: 1 != 1

assert.notEqual(1, '1');
// AssertionError: 1 != '1'
```

If the values are equal, an `AssertionError` is thrown with a `message` property set equal to the value of the `message` parameter. If the `message` parameter is undefined, a default error message is assigned. If the `message` parameter is an instance of an [`Error`][] then it will be thrown instead of the `AssertionError`.

## assert.notStrictEqual(actual, expected[, message])<!-- YAML
added: v0.1.21
changes:

  - version: v10.0.0
    pr-url: https://github.com/nodejs/node/pull/17003
    description: Used comparison changed from Strict Equality to `Object.is()`
-->

* `actual` {any}
* `expected` {any}
* `message` {string|Error}

Tests strict inequality between the `actual` and `expected` parameters as determined by the [SameValue Comparison](https://tc39.github.io/ecma262/#sec-samevalue).

```js
const assert = require('assert').strict;

assert.notStrictEqual(1, 2);
// OK

assert.notStrictEqual(1, 1);
// AssertionError [ERR_ASSERTION]: Identical input passed to notStrictEqual: 1

assert.notStrictEqual(1, '1');
// OK
```

If the values are strictly equal, an `AssertionError` is thrown with a `message` property set equal to the value of the `message` parameter. If the `message` parameter is undefined, a default error message is assigned. If the `message` parameter is an instance of an [`Error`][] then it will be thrown instead of the `AssertionError`.

## assert.ok(value[, message])<!-- YAML
added: v0.1.21
changes:

  - version: v10.0.0
    pr-url: https://github.com/nodejs/node/pull/18319
    description: The `assert.ok()` (no arguments) will now use a predefined
                 error message.
-->

* `value` {any}
* `message` {string|Error}

Verifica se il `value` è vero. It is equivalent to `assert.equal(!!value, true, message)`.

If `value` is not truthy, an `AssertionError` is thrown with a `message` property set equal to the value of the `message` parameter. If the `message` parameter is `undefined`, a default error message is assigned. If the `message` parameter is an instance of an [`Error`][] then it will be thrown instead of the `AssertionError`. If no arguments are passed in at all `message` will be set to the string: ``'No value argument passed to `assert.ok()`'``.

Be aware that in the `repl` the error message will be different to the one thrown in a file! Vedi sotto per ulteriori dettagli.

```js
const assert = require('assert').strict;

assert.ok(true);
// OK
assert.ok(1);
// OK

assert.ok();
// AssertionError: No value argument passed to `assert.ok()`

assert.ok(false, 'it\'s false');
// AssertionError: it's false

// In the repl:
assert.ok(typeof 123 === 'string');
// AssertionError: false == true

// In a file (e.g. test.js):
assert.ok(typeof 123 === 'string');
// AssertionError: The expression evaluated to a falsy value:
//
//   assert.ok(typeof 123 === 'string')

assert.ok(false);
// AssertionError: The expression evaluated to a falsy value:
//
//   assert.ok(false)

assert.ok(0);
// AssertionError: The expression evaluated to a falsy value:
//
//   assert.ok(0)

// Using `assert()` works the same:
assert(0);
// AssertionError: The expression evaluated to a falsy value:
//
//   assert(0)
```

## assert.rejects(asyncFn\[, error\]\[, message\])<!-- YAML
added: v10.0.0
-->

* `asyncFn` {Function|Promise}

* `error` {RegExp|Function|Object|Error}

* `message` {string}

Awaits the `asyncFn` promise or, if `asyncFn` is a function, immediately calls the function and awaits the returned promise to complete. It will then check that the promise is rejected.

If `asyncFn` is a function and it throws an error synchronously, `assert.rejects()` will return a rejected `Promise` with that error. If the function does not return a promise, `assert.rejects()` will return a rejected `Promise` with an [`ERR_INVALID_RETURN_VALUE`][] error. In both cases the error handler is skipped.

Besides the async nature to await the completion behaves identically to [`assert.throws()`][].

If specified, `error` can be a [`Class`][], [`RegExp`][], a validation function, an object where each property will be tested for, or an instance of error where each property will be tested for including the non-enumerable `message` and `name` properties.

If specified, `message` will be the message provided by the `AssertionError` if the `asyncFn` fails to reject.

```js
(async () => {
  await assert.rejects(
    async () => {
      throw new TypeError('Wrong value');
    },
    {
      name: 'TypeError',
      message: 'Wrong value'
    }
  );
})();
```

```js
assert.rejects(
  Promise.reject(new Error('Wrong value')),
  Error
).then(() => {
  // ...
});
```

Da notare che `error` non può essere una stringa. If a string is provided as the second argument, then `error` is assumed to be omitted and the string will be used for `message` instead. Questo può portare ad errori easy-to-miss (facili da perdere). Please read the example in [`assert.throws()`][] carefully if using a string as the second argument gets considered.

## assert.strictEqual(actual, expected[, message])

<!-- YAML
added: v0.1.21
changes:

  - version: v10.0.0
    pr-url: https://github.com/nodejs/node/pull/17003
    description: Used comparison changed from Strict Equality to `Object.is()`
-->

* `actual` {any}
* `expected` {any}
* `message` {string|Error}

Tests strict equality between the `actual` and `expected` parameters as determined by the [SameValue Comparison](https://tc39.github.io/ecma262/#sec-samevalue).

```js
const assert = require('assert').strict;

assert.strictEqual(1, 2);
// AssertionError [ERR_ASSERTION]: Input A expected to strictly equal input B:
// + expected - actual
// - 1
// + 2

assert.strictEqual(1, 1);
// OK

assert.strictEqual(1, '1');
// AssertionError [ERR_ASSERTION]: Input A expected to strictly equal input B:
// + expected - actual
// - 1
// + '1'
```

If the values are not strictly equal, an `AssertionError` is thrown with a `message` property set equal to the value of the `message` parameter. If the `message` parameter is undefined, a default error message is assigned. If the `message` parameter is an instance of an [`Error`][] then it will be thrown instead of the `AssertionError`.

## assert.throws(fn\[, error\]\[, message\])<!-- YAML
added: v0.1.21
changes:

  - version: v10.2.0
    pr-url: https://github.com/nodejs/node/pull/20485
    description: The `error` parameter can be an object containing regular
                 expressions now.
  - version: v9.9.0
    pr-url: https://github.com/nodejs/node/pull/17584
    description: The `error` parameter can now be an object as well.
  - version: v4.2.0
    pr-url: https://github.com/nodejs/node/pull/3276
    description: The `error` parameter can now be an arrow function.
-->

* `fn` {Function}
* `error` {RegExp|Function|Object|Error}
* `message` {string}

Expects the function `fn` to throw an error.

If specified, `error` can be a [`Class`][], [`RegExp`][], a validation function, a validation object where each property will be tested for strict deep equality, or an instance of error where each property will be tested for strict deep equality including the non-enumerable `message` and `name` properties. When using an object, it is also possible to use a regular expression, when validating against a string property. See below for examples.

If specified, `message` will be appended to the message provided by the `AssertionError` if the `fn` call fails to throw or in case the error validation fails.

Custom validation object/error instance:

```js
const err = new TypeError('Wrong value');
err.code = 404;
err.foo = 'bar';
err.info = {
  nested: true,
  baz: 'text'
};
err.reg = /abc/i;

assert.throws(
  () => {
    throw err;
  },
  {
    name: 'TypeError',
    message: 'Wrong value',
    info: {
      nested: true,
      baz: 'text'
    }
    // Note that only properties on the validation object will be tested for.
    // Using nested objects requires all properties to be present. Otherwise
    // the validation is going to fail.
  }
);

// Using regular expressions to validate error properties:
assert.throws(
  () => {
    throw err;
  },
  {
    // The `name` and `message` properties are strings and using regular
    // expressions on those will match against the string. If they fail, an
    // error is thrown.
    name: /^TypeError$/,
    message: /Wrong/,
    foo: 'bar',
    info: {
      nested: true,
      // It is not possible to use regular expressions for nested properties!
      baz: 'text'
    },
    // The `reg` property contains a regular expression and only if the
    // validation object contains an identical regular expression, it is going
    // to pass.
    reg: /abc/i
  }
);

// Fails due to the different `message` and `name` properties:
assert.throws(
  () => {
    const otherErr = new Error('Not found');
    otherErr.code = 404;
    throw otherErr;
  },
  err // This tests for `message`, `name` and `code`.
);
```

Convalida instanceof utilizzando il constructor:

```js
assert.throws(
  () => {
    throw new Error('Wrong value');
  },
  Error
);
```

Convalida il messsaggio d'errore utilizzando [`RegExp`][]:

Using a regular expression runs `.toString` on the error object, and will therefore also include the error name.

```js
assert.throws(
  () => {
    throw new Error('Wrong value');
  },
  /^Error: Wrong value$/
);
```

Convalida del custom error:

```js
assert.throws(
  () => {
    throw new Error('Wrong value');
  },
  function(err) {
    if ((err instanceof Error) && /value/.test(err)) {
      return true;
    }
  },
  'unexpected error'
);
```

Da notare che `error` non può essere una stringa. If a string is provided as the second argument, then `error` is assumed to be omitted and the string will be used for `message` instead. Questo può portare ad errori easy-to-miss (facili da perdere). Using the same message as the thrown error message is going to result in an `ERR_AMBIGUOUS_ARGUMENT` error. Please read the example below carefully if using a string as the second argument gets considered:

```js
function throwingFirst() {
  throw new Error('First');
}
function throwingSecond() {
  throw new Error('Second');
}
function notThrowing() {}

// Il secondo argomento è una stringa e la funzione di input ha generato un errore.
// Il primo caso non verrà generato in quanto non corrisponde al messaggio di errore 
// generato dalla funzione di input!
assert.throws(throwingFirst, 'Second');
// Nel prossimo esempio il messaggio non ha alcun vantaggio sul messaggio proveniente 
// dall'errore e poiché non è chiaro se l'utente intendesse effettivamente farlo 
// corrispondere al messaggio di errore, Node.js ha generato un 
errore `ERR_AMBIGUOUS_ARGUMENT`.
assert.throws(throwingSecond, 'Second');
// Genera un errore:
// TypeError [ERR_AMBIGUOUS_ARGUMENT]

// La stringa viene utilizzata (come messaggio) solo nel caso in cui la funzione non viene eseguita:
assert.throws(notThrowing, 'Second');
// AssertionError [ERR_ASSERTION]: Missing expected exception: Second

// Se è stato ideato per corrispondere al messaggio di errore, allora fai questo:
assert.throws(throwingSecond, /Second$/);
// Non genera poiché i messaggi di errore corrispondono.
assert.throws(throwingFirst, /Second$/);
// Genera un errore:
// Error: First
//     at throwingFirst (repl:2:9)
```

Due to the confusing notation, it is recommended not to use a string as the second argument. Ciò potrebbe portare ad errori difficult-to-sport (difficili da individuare).